Workbook

Sheet Cleaned Table
A1: Link | B1: Restaurant_name | C1: Review_score | D1: No_of_reviews | E1: Price_range | F1: Open_time | G1: Review | H1: Address | I1: District classification.Latitude | J1: District classification.Longitude | K1: District | L1: Ward | M1: Price_bucket | N1: Time_bucket | O1: Rank | P1: Category | Q1: Local_vs_English | R1: Cafe_options
A2: https://www.google.com/maps/place/Hoang%E2%80%99s+Kitchen+-Vietnamese+cuisine+%26+Vegan+food/data=!4m7!3m6!1s0x31752f7c28d2133d:0xf4f42c414b22791c!8m2!3d10.774218!4d106.6966059!16s%2Fg%2F11w236c_vf!19sChIJPRPSKHwvdTERHHkiS0Es9PQ?authuser=0&hl=en&rclk=1 | B2: Hoang’s Kitchen -Vietnamese cuisine & Vegan food | C2: 4.9 | D2: 19105 | E2: ₫100–200K | F2: 0.41666667 | G2: "Delicious and amazing service!" | H2: 45 Thủ Khoa Huân | I2: 10.774218 | J2: 106.69661 | K2: District 1 | L2: Bến Thành | M2: Medium | N2: Morning | O2: 1 | P2: Modern vegan / plant-based | Q2: English / international-facing | R2: No
A3: https://www.google.com/maps/place/Ben+Nghe+Street+Food/data=!4m7!3m6!1s0x31752f38d6d12d4b:0x9a6eb30ab7589d13!8m2!3d10.7773167!4d106.6977562!16s%2Fg%2F11bxgb8ltc!19sChIJSy3R1jgvdTERE51Ytwqzbpo?authuser=0&hl=en&rclk=1 | B3: Ben Nghe Street Food | C3: 4.3 | D3: 12589 | E3: ₫100–200K | G3: "Great location, large selection of types, both | H3: 134 Nam Kỳ Khởi Nghĩa | I3: 10.777317 | J3: 106.69776 | K3: District 1 | L3: Bến Thành | M3: Medium | N3: No data | O3: 2 | P3: Quick-service / noodle / banh mi vegetarian | Q3: English / international-facing | R3: No
A4: https://www.google.com/maps/place/De+Tham+Restaurant+-+Vietnamese+cuisine+%26+vegetarian+Food/data=!4m7!3m6!1s0x31752fe948e20f7f:0x5a5f1358daf89ccf!8m2!3d10.7682442!4d106.6936304!16s%2Fg%2F11why8sz0c!19sChIJfw_iSOkvdTERz5z42lgTX1o?authuser=0&hl=en&rclk=1 | B4: De Tham Restaurant - Vietnamese cuisine & vegetarian Food | C4: 4.9 | D4: 11763 | E4: ₫100–200K | F4: 0.4375 | G4: "We ordered everything here and the | H4: 258 Đề Thám | I4: 10.768244 | J4: 106.69363 | K4: District 1 | L4: Phạm Ngũ Lão | M4: Medium | N4: Morning | O4: 3 | P4: Vegetarian bistro / casual dining | Q4: English / international-facing | R4: No
A5: https://www.google.com/maps/place/Tung%27s+Restaurant+-+Vietnamese+Cuisine+%26+vegetarian+Food/data=!4m7!3m6!1s0x31752f59e15c67e9:0x7a43f830bff40c1!8m2!3d10.7726481!4d106.6964836!16s%2Fg%2F11v_25lpjr!19sChIJ6Wdc4VkvdTERwUD_C4M_pAc?authuser=0&hl=en&rclk=1 | B5: Tung's Restaurant - Vietnamese Cuisine & vegetarian Food | C5: 4.9 | D5: 11585 | E5: ₫100–200K | F5: 0.41666667 | G5: "The options were perfectly made, best mock beef I ve ever had." | H5: 230 Lê Thánh Tôn | I5: 10.772648 | J5: 106.69648 | K5: District 1 | L5: Phạm Ngũ Lão | M5: Medium | N5: Morning | O5: 4 | P5: Vegetarian bistro / casual dining | Q5: English / international-facing | R5: No
A6: https://www.google.com/maps/place/Propaganda+Vietnamese+Bistro/data=!4m7!3m6!1s0x31752f378dabe5db:0x635cd76f30bd0737!8m2!3d10.7787806!4d106.6981583!16s%2Fg%2F1pyqmjd_t!19sChIJ2-WrjTcvdTERNwe9MG_XXGM?authuser=0&hl=en&rclk=1 | B6: Propaganda Vietnamese Bistro | C6: 4.4 | D6: 4565 | E6: ₫200–300K | G6: "Very tasty options and a cute space." | H6: 21 Đ. Hàn Thuyên | I6: 10.778781 | J6: 106.69816 | K6: District 1 | L6: Bến Nghé | M6: Premium | N6: No data | O6: 7 | P6: Vegetarian bistro / casual dining | Q6: English / international-facing | R6: No
A7: https://www.google.com/maps/place/Soumaki+-+Your+Healthy+Food+Soulmate+-+L%C3%BD+T%E1%BB%B1+Tr%E1%BB%8Dng/data=!4m7!3m6!1s0x31752fd9351b8d79:0xcee998c37f0eb018!8m2!3d10.7771971!4d106.700107!16s%2Fg%2F11s3vl41pc!19sChIJeY0bNdkvdTERGLAOf8OY6c4?authuser=0&hl=en&rclk=1 | B7: Soumaki - Your Healthy Food Soulmate - Lý Tự Trọng | C7: 4.9 | D7: 3679 | E7: ₫100–200K | G7: "The was so tasty and healthy and it filled me up!" | H7: 42 Lý Tự Trọng | I7: 10.777197 | J7: 106.70011 | K7: District 1 | L7: Bến Nghé | M7: Medium | N7: No data | O7: 8 | P7: Modern vegan / plant-based | Q7: English / international-facing | R7: No
A8: https://www.google.com/maps/place/Heart+of+Darkness+Craft+Brewery/data=!4m7!3m6!1s0x31752f48f43430cd:0x51c14d0271469c87!8m2!3d10.7798149!4d106.7029294!16s%2Fg%2F11crxw6gy6!19sChIJzTA09EgvdTERh5xGcQJNwVE?authuser=0&hl=en&rclk=1 | B8: Heart of Darkness Craft Brewery | C8: 4.6 | D8: 3635 | E8: ₫200–300K | G8: "Meat-eaters, vegetarians and can all find PLENTY to eat." | H8: 31D Lý Tự Trọng | I8: 10.779815 | J8: 106.70293 | K8: District 1 | L8: Bến Nghé | M8: Premium | N8: No data | O8: 9 | P8: Vegetarian bistro / casual dining | Q8: English / international-facing | R8: No
A9: https://www.google.com/maps/place/Dahi+Handi+Indian+Restaurant/data=!4m7!3m6!1s0x31752f7a7d473e5d:0x1835902d3fa5e1ca!8m2!3d10.7761731!4d106.7048075!16s%2Fg%2F11gl12kgyd!19sChIJXT5HfXovdTERyuGlPy2QNRg?authuser=0&hl=en&rclk=1 | B9: Dahi Handi Indian Restaurant | C9: 4.8 | D9: 3412 | E9: ₫200–300K | G9: "Finger licking good and service with a smile by Johnny." | H9: 23 Đông Du | I9: 10.776173 | J9: 106.70481 | K9: District 1 | L9: Bến Nghé | M9: Premium | N9: No data | O9: 10 | P9: Vegetarian bistro / casual dining | Q9: English / international-facing | R9: No
A10: https://www.google.com/maps/place/My+Banh+Mi/data=!4m7!3m6!1s0x31752f481a3d8727:0xf40b76660ec7ebf!8m2!3d10.7791987!4d106.7005186!16s%2Fg%2F11btwr4dq9!19sChIJJ4c9GkgvdTERv37sYGa3QA8?authuser=0&hl=en&rclk=1 | B10: My Banh Mi | C10: 4.6 | D10: 3201 | E10: ₫100–200K | G10: "Excellent with | H10: 57 Nguyễn Du | I10: 10.779199 | J10: 106.70052 | K10: District 1 | L10: Bến Nghé | M10: Medium | N10: No data | O10: 11 | P10: Quick-service / noodle / banh mi vegetarian | Q10: English / international-facing | R10: No
A11: https://www.google.com/maps/place/Poke+Saigon+Ly+Tu+Trong/data=!4m7!3m6!1s0x31752f47f450b265:0xa46f765f0dea01e8!8m2!3d10.7771626!4d106.7001507!16s%2Fg%2F11g020cwyh!19sChIJZbJQ9EcvdTER6AHqDV92b6Q?authuser=0&hl=en&rclk=1 | B11: Poke Saigon Ly Tu Trong | C11: 4.8 | D11: 2821 | E11: ₫100–200K | G11: "Amazing fresh, tasty, nutritious served with a warm welcoming smile." | H11: First floor, 42 Bis Lý Tự Trọng | I11: 10.777163 | J11: 106.70015 | K11: District 1 | L11: Bến Nghé | M11: Medium | N11: No data | O11: 12 | P11: Modern vegan / plant-based | Q11: English / international-facing | R11: No
A12: https://www.google.com/maps/place/Tanishq+Indian+Vegetarian+Restaurant/data=!4m7!3m6!1s0x31752f005cdd2991:0x5e8b095e1f1ff220!8m2!3d10.7719456!4d106.6939273!16s%2Fg%2F11w9kmg0rf!19sChIJkSndXAAvdTERIPIfH14Ji14?authuser=0&hl=en&rclk=1 | B12: Tanishq Indian Vegetarian Restaurant | C12: 4.9 | D12: 2810 | E12: ₫200–300K | F12: 0.33333333 | G12: "We are and left completely full and happy." | H12: 258 Lý Tự Trọng | I12: 10.771946 | J12: 106.69393 | K12: District 1 | L12: Phạm Ngũ Lão | M12: Premium | N12: Morning | O12: 13 | P12: Vegetarian bistro / casual dining | Q12: English / international-facing | R12: No
A13: https://www.google.com/maps/place/Heal+and+Celeb+Vegan+Restaurant/data=!4m7!3m6!1s0x317529dc13f3f3b9:0xffd3cac3c0af494c!8m2!3d10.793559!4d106.686756!16s%2Fg%2F11t0rzqfyp!19sChIJufPzE9wpdTERTEmvwMPK0_8?authuser=0&hl=en&rclk=1 | B13: Heal and Celeb Vegan Restaurant | C13: 4.9 | D13: 2355 | E13: ₫100–200K | F13: 0.39583333 | G13: "Every dish was bursting with flavor, showcasing the best of cuisine." | H13: 27/1 Nguyễn Văn Nguyễn | I13: 10.793559 | J13: 106.68676 | K13: District 1 | L13: Tân Định | M13: Medium | N13: Morning | O13: 14 | P13: Modern vegan / plant-based | Q13: English / international-facing | R13: No
A14: https://www.google.com/maps/place/Hoa+T%C3%BAc+Saigon/data=!4m7!3m6!1s0x31752f4627907e63:0x228869e80686c24a!8m2!3d10.7785004!4d106.7037745!16s%2Fg%2F11g8bqp8hn!19sChIJY36QJ0YvdTERSsKGBuhpiCI?authuser=0&hl=en&rclk=1 | B14: Hoa Túc Saigon | C14: 4.5 | D14: 2353 | E14: ₫200–300K | G14: "Delicious and the understood what a gluten allergy is." | H14: 74/7 Hai Bà Trưng | I14: 10.7785 | J14: 106.70377 | K14: District 1 | L14: Bến Nghé | M14: Premium | N14: No data | O14: 15 | P14: Vegetarian bistro / casual dining | Q14: English / international-facing | R14: No
A15: https://www.google.com/maps/place/Be+An+Vegetarian+Bistro/data=!4m7!3m6!1s0x31752ffbfbe36a49:0x9c10bfad0d4fdd69!8m2!3d10.7733531!4d106.7038615!16s%2Fg%2F11fs2zs_3d!19sChIJSWrj-_svdTERad1PDa2_EJw?authuser=0&hl=en&rclk=1 | B15: Be An Vegetarian Bistro | C15: 4.8 | D15: 2220 | E15: ₫200–300K | F15: 0.41666667 | G15: "Gorgeous , lovely staff and the most delicious | H15: Saigon Garden, 99 Nguyễn Huệ | I15: 10.773353 | J15: 106.70386 | K15: District 1 | L15: Nguyễn Thái Bình | M15: Premium | N15: Morning | O15: 16 | P15: Vegetarian bistro / casual dining | Q15: English / international-facing | R15: No
A16: https://www.google.com/maps/place/G%C3%A1nh+-+Truly+Vietnamese+Cuisine/data=!4m7!3m6!1s0x31752f4934863955:0xe45e41df1006ad7a!8m2!3d10.77714!4d106.704236!16s%2Fg%2F11bxkpfpjs!19sChIJVTmGNEkvdTEReq0GEN9BXuQ?authuser=0&hl=en&rclk=1 | B16: Gánh - Truly Vietnamese Cuisine | C16: 4.5 | D16: 2197 | E16: ₫200–300K | G16: "Amazing healthy , great music and ambience" | H16: 91 Hai Bà Trưng | I16: 10.77714 | J16: 106.70424 | K16: District 1 | L16: Bến Nghé | M16: Premium | N16: No data | O16: 17 | P16: Local Vietnamese vegetarian | Q16: Mixed local + English-facing | R16: No
A17: https://www.google.com/maps/place/Au+Parc+Caf%C3%A9/data=!4m7!3m6!1s0x31752f378c9f5bf3:0x7e1388eb0419e27a!8m2!3d10.7787276!4d106.6980638!16s%2Fg%2F1hc2zh7r9!19sChIJ81ufjDcvdTEReuIZBOuIE34?authuser=0&hl=en&rclk=1 | B17: Au Parc Café | C17: 4.5 | D17: 2112 | E17: ₫200–300K | G17: "Very good - clean, healthy and fast for a full fresh meal." | H17: 23 Đ. Hàn Thuyên | I17: 10.778728 | J17: 106.69806 | K17: District 1 | L17: Bến Nghé | M17: Premium | N17: No data | O17: 19 | P17: Vegetarian cafe / light dining | Q17: English / international-facing | R17: Yes
A18: https://www.google.com/maps/place/21Grams+Vegetarian/data=!4m7!3m6!1s0x31752f616c7ba2f3:0xf25f36475c2b39b3!8m2!3d10.774103!4d106.7041327!16s%2Fg%2F11ty14p2l3!19sChIJ86J7bGEvdTERszkrXEc2X_I?authuser=0&hl=en&rclk=1 | B18: 21Grams Vegetarian | C18: 4.9 | D18: 1857 | E18: ₫100–200K | F18: 0.41666667 | G18: "All with | H18: 42 Nguyễn Huệ | I18: 10.774103 | J18: 106.70413 | K18: District 1 | L18: Bến Nghé | M18: Medium | N18: Morning | O18: 21 | P18: Vegetarian bistro / casual dining | Q18: English / international-facing | R18: No
A19: https://www.google.com/maps/place/Curry-licious+Indian+Restaurant/data=!4m7!3m6!1s0x31752ff05dc82141:0x8bf6105890ee8927!8m2!3d10.7771121!4d106.7039749!16s%2Fg%2F11x90vs602!19sChIJQSHIXfAvdTERJ4nukFgQ9os?authuser=0&hl=en&rclk=1 | B19: Curry-licious Indian Restaurant | C19: 4.9 | D19: 1815 | E19: ₫200–300K | G19: "We tried vegetarians options and all was awesome." | H19: 9 Công trường Lam Sơn | I19: 10.777112 | J19: 106.70397 | K19: District 1 | L19: Bến Nghé | M19: Premium | N19: No data | O19: 22 | P19: Vegetarian bistro / casual dining | Q19: English / international-facing | R19: No
A20: https://www.google.com/maps/place/B%C3%A1nh+M%C3%AC+The+One+%E2%80%93+Vietnamese+Sandwich+%26+Vegan+Food/data=!4m7!3m6!1s0x31752fce14c0893f:0x293d0fc78c33785e!8m2!3d10.7723259!4d106.6945746!16s%2Fg%2F11w2fr19ss!19sChIJP4nAFM4vdTERXngzjMcPPSk?authuser=0&hl=en&rclk=1 | B20: Bánh Mì The One – Vietnamese Sandwich & Vegan Food | C20: 4.9 | D20: 1600 | E20: ₫1–100,000 | G20: "Delicious, both and meat options, super friendly staff 🫶🏻" | H20: 234 Lý Tự Trọng | I20: 10.772326 | J20: 106.69457 | K20: District 1 | L20: Phạm Ngũ Lão | M20: Low | N20: No data | O20: 23 | P20: Quick-service / noodle / banh mi vegetarian | Q20: English / international-facing | R20: No
A21: https://www.google.com/maps/place/Shamballa+Vegetarian,+Restaurant+%26+Lounge+-+Sai+Gon/data=!4m7!3m6!1s0x31752fabc8d54ad3:0xc175c07deb731e0d!8m2!3d10.7795135!4d106.7026522!16s%2Fg%2F11jvbdshld!19sChIJ00rVyKsvdTERDR5z633AdcE?authuser=0&hl=en&rclk=1 | B21: Shamballa Vegetarian, Restaurant & Lounge - Sai Gon | C21: 4.7 | D21: 1452 | E21: ₫200–300K | F21: 0.375 | G21: "Amazing ambience (sitting outside) and served delicious ." | H21: 31 Lý Tự Trọng | I21: 10.779514 | J21: 106.70265 | K21: District 1 | L21: Bến Nghé | M21: Premium | N21: Morning | O21: 24 | P21: Vegetarian bistro / casual dining | Q21: English / international-facing | R21: No
A22: https://www.google.com/maps/place/IVEGAN+SUPERSHOP+BEN+THANH+-+HEALTHY+PLANT+BASED+CAFE/data=!4m7!3m6!1s0x317527178384a5e9:0x6bd0b476886d57!8m2!3d10.7716643!4d106.6950738!16s%2Fg%2F11kqq40qrz!19sChIJ6aWEgxcndTERV22IdrTQawA?authuser=0&hl=en&rclk=1 | B22: IVEGAN SUPERSHOP BEN THANH - HEALTHY PLANT BASED CAFE | C22: 4.9 | D22: 1419 | E22: ₫100–200K | F22: 0.35416667 | G22: "Delicious , cute cozy space and nice staff." | H22: 29 Lê Anh Xuân | I22: 10.771664 | J22: 106.69507 | K22: District 1 | L22: Bến Thành | M22: Medium | N22: Morning | O22: 25 | P22: Vegetarian cafe / light dining | Q22: English / international-facing | R22: Yes
A23: https://www.google.com/maps/place/Roots+Plant-based+Cafe+-+Ben+Thanh/data=!4m7!3m6!1s0x31752f2c5b5c23f9:0x37dd5beb607c8cff!8m2!3d10.7741206!4d106.6975015!16s%2Fg%2F11xcvlc9qw!19sChIJ-SNcWywvdTER_4x8YOtb3Tc?authuser=0&hl=en&rclk=1 | B23: Roots Plant-based Cafe - Ben Thanh | C23: 4.9 | D23: 1407 | E23: ₫100–200K | F23: 0.33333333 | G23: "Great in a calm stylish setting." | H23: 113-115 Lý Tự Trọng | I23: 10.774121 | J23: 106.6975 | K23: District 1 | L23: Bến Thành | M23: Medium | N23: Morning | O23: 26 | P23: Vegetarian cafe / light dining | Q23: English / international-facing | R23: Yes
A24: https://www.google.com/maps/place/Be+An+Vegetarian+Bistro/data=!4m7!3m6!1s0x31752fc59340bdeb:0xdf3513c4d4fb4ba!8m2!3d10.784419!4d106.697799!16s%2Fg%2F11kjf2bthm!19sChIJ671Ak8UvdTERurRPTTxR8w0?authuser=0&hl=en&rclk=1 | B24: Be An Vegetarian Bistro | C24: 4.8 | D24: 1365 | E24: ₫200–300K | G24: Dine-in Delivery | H24: 11B Trần Cao Vân | I24: 10.784419 | J24: 106.6978 | K24: District 1 | L24: Đa Kao | M24: Premium | N24: No data | O24: 28 | P24: Vegetarian bistro / casual dining | Q24: English / international-facing | R24: No
A25: https://www.google.com/maps/place/Be+An+Vegetarian+Bistro/data=!4m7!3m6!1s0x31752fc59340bdeb:0xdf3513c4d4fb4ba!8m2!3d10.7844192!4d106.6977993!16s%2Fg%2F11kjf2bthm!19sChIJ671Ak8UvdTERurRPTTxR8w0?authuser=0&hl=en&rclk=1 | B25: Be An Vegetarian Bistro | C25: 4.8 | D25: 1365 | E25: ₫200–300K | F25: 0.41666667 | G25: "Amazing , calming atmosphere" | H25: 11B Trần Cao Vân | I25: 10.784419 | J25: 106.6978 | K25: District 1 | L25: Đa Kao | M25: Premium | N25: Morning | O25: 27 | P25: Vegetarian bistro / casual dining | Q25: English / international-facing | R25: No
A26: https://www.google.com/maps/place/V%E1%BB%8B+Qu%C3%AA+Kitchen/data=!4m7!3m6!1s0x31752fe59e20471f:0x169be80586c609d8!8m2!3d10.7715986!4d106.6885602!16s%2Fg%2F11rg6q_gvv!19sChIJH0cgnuUvdTER2AnGhgXomxY?authuser=0&hl=en&rclk=1 | B26: Vị Quê Kitchen | C26: 4.7 | D26: 1269 | E26: ₫100–200K | F26: 0.41666667 | G26: "Delicious , amazing drinks, and great atmosphere!" | H26: 110 Sương Nguyệt Anh | I26: 10.771599 | J26: 106.68856 | K26: District 1 | L26: Bến Thành | M26: Medium | N26: Morning | O26: 29 | P26: Vegetarian bistro / casual dining | Q26: English / international-facing | R26: No
A27: https://www.google.com/maps/place/Prem+%26+Pi+Vegetarian+Bistro+-+since+2013/data=!4m7!3m6!1s0x31752f3b3c7990e9:0xccf0c5443c10be6d!8m2!3d10.786464!4d106.694317!16s%2Fg%2F11b6hqmm49!19sChIJ6ZB5PDsvdTERbb4QPETF8Mw?authuser=0&hl=en&rclk=1 | B27: Prem & Pi Vegetarian Bistro - since 2013 | C27: 4.5 | D27: 1242 | E27: ₫200–300K | F27: 0.41666667 | G27: "Beautiful atmosphere for delicious ." | H27: 187/15 Điện Biên Phủ | I27: 10.786464 | J27: 106.69432 | K27: District 1 | L27: Đa Kao | M27: Premium | N27: Morning | O27: 30 | P27: Vegetarian bistro / casual dining | Q27: English / international-facing | R27: No
A28: https://www.google.com/maps/place/Le+Corto/data=!4m7!3m6!1s0x31752f46183b600f:0x2d05f35baaca375b!8m2!3d10.7778086!4d106.7046515!16s%2Fg%2F11cms299_3!19sChIJD2A7GEYvdTERWzfKqlvzBS0?authuser=0&hl=en&rclk=1 | B28: Le Corto | C28: 4.5 | D28: 1201 | E28: ₫1,000,000+ | F28: 0.72916667 | G28: "Creative presentation, delicious ." | H28: 5D Nguyễn Siêu | I28: 10.777809 | J28: 106.70465 | K28: District 1 | L28: Bến Nghé | M28: No data | N28: Afternoon | O28: 31 | P28: Vegetarian bistro / casual dining | Q28: English / international-facing | R28: No
A29: https://www.google.com/maps/place/San+May+Cafe+%26+Vegetarian+Restaurant/data=!4m7!3m6!1s0x31752f351f00d393:0x2a4665bbd901d58f!8m2!3d10.7889806!4d106.6982583!16s%2Fg%2F1q6h_yzwz!19sChIJk9MAHzUvdTERj9UB2btlRio?authuser=0&hl=en&rclk=1 | B29: San May Cafe & Vegetarian Restaurant | C29: 4.3 | D29: 1061 | E29: ₫100–200K | F29: 0.33333333 | G29: "Delicious with lots of different and interesting options." | H29: 155 Nguyễn Văn Thủ | I29: 10.788981 | J29: 106.69826 | K29: District 1 | L29: Đa Kao | M29: Medium | N29: Morning | O29: 32 | P29: Vegetarian cafe / light dining | Q29: English / international-facing | R29: Yes
A30: https://www.google.com/maps/place/N%E1%BA%A5m+-+Vegetarian+Bistro/data=!4m7!3m6!1s0x31752ffe37d3b463:0x31b9b1ae10caf841!8m2!3d10.7888741!4d106.6916512!16s%2Fg%2F11srggl7x8!19sChIJY7TTN_4vdTERQfjKEK6xuTE?authuser=0&hl=en&rclk=1 | B30: Nấm - Vegetarian Bistro | C30: 4.9 | D30: 1025 | E30: ₫100–200K | F30: 0.41666667 | G30: "Really great , friendly staff and a calm atmosphere" | H30: 67C Đinh Công Tráng | I30: 10.788874 | J30: 106.69165 | K30: District 1 | L30: Tân Định | M30: Medium | N30: Morning | O30: 33 | P30: Vegetarian bistro / casual dining | Q30: English / international-facing | R30: No
A31: https://www.google.com/maps/place/S%C3%A0i+G%C3%B2n+Kitchen+Vina/data=!4m7!3m6!1s0x31752fa059f65bd7:0x8e9d22f08651a127!8m2!3d10.778228!4d106.6990193!16s%2Fg%2F11vz3b_sg9!19sChIJ11v2WaAvdTERJ6FRhvAinY4?authuser=0&hl=en&rclk=1 | B31: Sài Gòn Kitchen Vina | C31: 4.7 | D31: 1024 | E31: ₫100–200K | G31: "They have a great menu, good options & friendly staff." | H31: 86 Nguyễn Du | I31: 10.778228 | J31: 106.69902 | K31: District 1 | L31: Bến Thành | M31: Medium | N31: No data | O31: 34 | P31: Local Vietnamese vegetarian | Q31: Mixed local + English-facing | R31: No
A32: https://www.google.com/maps/place/7+Bridges+Craft+Beer+Taproom+%26+Restaurant+%2F+L%C3%AA+Th%C3%A1nh+T%C3%B4n/data=!4m7!3m6!1s0x31752f5b858ed635:0xf6afab1d3bbba627!8m2!3d10.7802418!4d106.7046589!16s%2Fg%2F11q26lk9hl!19sChIJNdaOhVsvdTERJ6a7Ox2rr_Y?authuser=0&hl=en&rclk=1 | B32: 7 Bridges Craft Beer Taproom & Restaurant / Lê Thánh Tôn | C32: 4.6 | D32: 954 | E32: ₫200–300K | G32: "Delicious , friendly service and fun location." | H32: 15B/12 Lê Thánh Tôn | I32: 10.780242 | J32: 106.70466 | K32: District 1 | L32: Bến Nghé | M32: Premium | N32: No data | O32: 36 | P32: Vegetarian bistro / casual dining | Q32: English / international-facing | R32: No
A33: https://www.google.com/maps/place/Tib+-+Hue+Restaurant/data=!4m7!3m6!1s0x31752f34773a47e3:0x62842bc6c1157c15!8m2!3d10.7858338!4d106.6942744!16s%2Fg%2F1vpq4c2m!19sChIJ40c6dzQvdTERFXwVwcYrhGI?authuser=0&hl=en&rclk=1 | B33: Tib - Hue Restaurant | C33: 4.3 | D33: 916 | E33: $$ | F33: 0.45833333 | G33: "Amazing place in folk style, found a delicious menu, recommend" | H33: 187 Ter Hai Bà Trưng | I33: 10.785834 | J33: 106.69427 | K33: District 1 | L33: Đa Kao | M33: No data | N33: Lunch | O33: 37 | P33: Vegetarian bistro / casual dining | Q33: English / international-facing | R33: No
A34: https://www.google.com/maps/place/La+Moi+plant-based+Restaurant/data=!4m7!3m6!1s0x31752fb36bbd2f47:0x35c6b390bd1bdfcf!8m2!3d10.778431!4d106.699046!16s%2Fg%2F11k4qvqc29!19sChIJRy-9a7MvdTERz98bvZCzxjU?authuser=0&hl=en&rclk=1 | B34: La Moi plant-based Restaurant | C34: 4.7 | D34: 910 | E34: ₫200–300K | F34: 0.33333333 | G34: "The Pad Thai was a flavor explosion, setting a high bar for cuisine." | H34: 84 Nguyễn Du | I34: 10.778431 | J34: 106.69905 | K34: District 1 | L34: Bến Thành | M34: Premium | N34: Morning | O34: 38 | P34: Modern vegan / plant-based | Q34: English / international-facing | R34: No
A35: https://www.google.com/maps/place/Li+Bai+Authentic+Cantonese+Restaurant/data=!4m7!3m6!1s0x31752f91eed42415:0xa178e41d3c672dda!8m2!3d10.7757259!4d106.703781!16s%2Fg%2F11sm70dxh6!19sChIJFSTU7pEvdTER2i1nPB3keKE?authuser=0&hl=en&rclk=1 | B35: Li Bai Authentic Cantonese Restaurant | C35: 4.8 | D35: 882 | E35: ₫1,000,000+ | F35: 0.75 | G35: "Not only the was delicious, I was surprised by the attentive staff." | H35: Sheraton Saigon Grand Opera Hotel, 88 Đồng Khởi | I35: 10.775726 | J35: 106.70378 | K35: District 1 | L35: Bến Nghé | M35: No data | N35: Night | O35: 39 | P35: Vegetarian bistro / casual dining | Q35: English / international-facing | R35: No
A36: https://www.google.com/maps/place/Bon%E2%80%99s+Vegan+Bistro+-+B%C3%A1nh+M%C3%AC+%26+Coffee/data=!4m7!3m6!1s0x31752fac15ce84d1:0xb3ae51a8927c2cb!8m2!3d10.7702529!4d106.7020348!16s%2Fg%2F11j72t29ws!19sChIJ0YTOFawvdTERy8IniRrlOgs?authuser=0&hl=en&rclk=1 | B36: Bon’s Vegan Bistro - Bánh Mì & Coffee | C36: 4.9 | D36: 834 | E36: ₫100–200K | F36: 0.33333333 | G36: "Delicious , the loveliest service and a beautiful environment." | H36: 89/8 Hàm Nghi | I36: 10.770253 | J36: 106.70203 | K36: District 1 | L36: Nguyễn Thái Bình | M36: Medium | N36: Morning | O36: 40 | P36: Quick-service / noodle / banh mi vegetarian | Q36: English / international-facing | R36: Yes
A37: https://www.google.com/maps/place/Nh%C3%A0+h%C3%A0ng+thu%E1%BA%A7n+chay+Ngon+Vegan+Dining+%26+Cafe+-+Tr%E1%BA%A7n+Cao+V%C3%A2n/data=!4m7!3m6!1s0x31752f005f2a10c3:0xe910019d74900f91!8m2!3d10.7844858!4d106.6975065!16s%2Fg%2F11yb67g06h!19sChIJwxAqXwAvdTERkQ-QdJ0BEOk?authuser=0&hl=en&rclk=1 | B37: Nhà hàng thuần chay Ngon Vegan Dining & Cafe - Trần Cao Vân | C37: 4.8 | D37: 809 | E37: ₫100–200K | F37: 0.41666667 | G37: "Great , a really cozy atmosphere, and very generous portions." | H37: 16 Trần Cao Vân | I37: 10.784486 | J37: 106.69751 | K37: District 1 | L37: Đa Kao | M37: Medium | N37: Morning | O37: 41 | P37: Vegetarian cafe / light dining | Q37: Mixed local + English-facing | R37: Yes
A38: https://www.google.com/maps/place/LuLi%E2%80%99s+Kitchen+-+District+1/data=!4m7!3m6!1s0x3175273ff56582c7:0xdd300353ed536440!8m2!3d10.7785192!4d106.6981803!16s%2Fg%2F11y1hqb5vt!19sChIJx4Jl9T8ndTERQGRT7VMDMN0?authuser=0&hl=en&rclk=1 | B38: LuLi’s Kitchen - District 1 | C38: 4.9 | D38: 755 | E38: ₫100–200K | G38: "Very accommodating for my gluten free needs too." | H38: Pasteur/182A Ward | I38: 10.778519 | J38: 106.69818 | K38: District 1 | L38: Bến Nghé | M38: Medium | N38: No data | O38: 43 | P38: Local Vietnamese vegetarian | Q38: Mixed local + English-facing | R38: No
A39: https://www.google.com/maps/place/Lim+Veggie+Bistro/data=!4m7!3m6!1s0x317529bb1656f27d:0xc74b19bde30c8bc0!8m2!3d10.7810504!4d106.7061501!16s%2Fg%2F11kb92ssq9!19sChIJffJWFrspdTERwIsM470ZS8c?authuser=0&hl=en&rclk=1 | B39: Lim Veggie Bistro | C39: 4.9 | D39: 664 | E39: ₫100–200K | F39: 0.375 | G39: "Exceptional and atmosphere." | H39: 07 Ngô Văn Năm | I39: 10.78105 | J39: 106.70615 | K39: District 1 | L39: Bến Nghé | M39: Medium | N39: Morning | O39: 44 | P39: Vegetarian bistro / casual dining | Q39: English / international-facing | R39: No
A40: https://www.google.com/maps/place/M%C3%8A+RAU+Vegetarian+-+Buffet+L%E1%BA%A9u+Rau+N%E1%BA%A5m/data=!4m7!3m6!1s0x31752f0001fe0033:0x3a0e0448b5313e8a!8m2!3d10.7871204!4d106.6960532!16s%2Fg%2F11vz620fyq!19sChIJMwD-AQAvdTERij4xtUgEDjo?authuser=0&hl=en&rclk=1 | B40: MÊ RAU Vegetarian - Buffet Lẩu Rau Nấm | C40: 4.3 | D40: 642 | E40: ₫100–200K | F40: 0.4375 | G40: "It comes with tons of veggie, tofu, and broth selection." | H40: 174 Nguyễn Văn Thủ | I40: 10.78712 | J40: 106.69605 | K40: District 1 | L40: Đa Kao | M40: Medium | N40: Morning | O40: 45 | P40: Buffet / hotpot vegetarian | Q40: English / international-facing | R40: No
...

Sheet Dictionary
A1: Field Name | B1: Data Type | C1: Description
A2: Link | B2: Text / URL | C2: Google Maps listing URL for each restaurant.
A3: Restaurant_name | B3: Text | C3: Cleaned restaurant name from Google Maps.
A4: Review_score | B4: Decimal number | C4: Google Maps average rating score.
A5: No_of_reviews | B5: Whole number | C5: Number of Google Maps reviews for the restaurant.
A6: Price_range | B6: Text / category | C6: Raw price range label captured from Google Maps.
A7: Open_time | B7: Time / Excel serial | C7: Opening time captured from listing, stored as Excel time fraction.
A8: Review | B8: Text | C8: Representative review snippet captured from Google Maps.
A9: Address | B9: Text | C9: Street address of the restaurant.
A10: District classification.Latitude | B10: Decimal number | C10: Latitude coordinate from the district classification process.
A11: District classification.Longitude | B11: Decimal number | C11: Longitude coordinate from the district classification process.
A12: District | B12: Category | C12: Cleaned district group used for analysis.
... A19: Cafe_options | B19: Yes/No | C19: Flag showing whether the concept includes cafe, coffee, tea, or light-dining cues.

Sheet Recommended districts
A1: District | B1: Key characteristics | C1: Suitable foreigner type | D1: Stay term
A2: District 1 | B2: CBD, tourist center, financial/corporate offices, walkable but expensive and crowded | C2: Business travelers, short-stay expats, people working in CBD | D2: Short–medium term
A3: District 2 | B3: Expat enclave, many serviced apartments, villas, cafes, restaurants, gyms, nightlife, international school | C3: Western expats, teachers, young professionals, expat families | D3: Short–long term
A4: District 3 | B4: Near District 1 but calmer, cheaper, tree-lined streets, cafes, gyms, local lifestyle | C4: Expats who want central location without District 1 chaos | D4: Medium–long term
A5: District 7 | B5: Quiet, planned, green, wide roads, malls, parks, international schools, Korean community | C5: Families, Korean expats, long-term professionals | D5: Long-term
A6: Binh Thanh | B6: Close to District 1, many condos, cafes, local food, Vinhomes/Landmark 81 area is more premium | C6: Young professionals, teachers, people wanting city access but lower cost | D6: Medium–long term

Sheet Location
A2: No of restaurant by district | D2: No of review by district | G2: Review per restaurant | P2: No of review of Top 3 restaurant | S2: Review per restaurant by ward
A4: Row Labels | B4: No of restaurant | D4: Row Labels | E4: Sum of No_of_reviews | G4: Row Labels | H4: Total district restaurant | I4: Total district review | J4: No of review per restaurant | K4: Average review per restaurant: | L4: Avg review score | M4: No of review of Top 5 restaurant | N4: % Top 5 Review | P4: Rank | Q4: (Multiple Items) | S4: District | T4: Ward | U4: No of restaurant | V4: Sum of No_of_reviews | W4: No of review per restaurant
A5: Binh Thanh | B5: 9 | D5: Binh Thanh | E5: 0.0093107707 | G5: District 1 | H5: =COUNTIF('Cleaned Table'!K:K,Location!G5) -> 73 | I5: =SUMIF('Cleaned Table'!K:K,Location!G5,'Cleaned Table'!D:D) -> 128619 | J5: =I5/H5 -> 1761.9041 | K5: =Location!I10/Location!H10 -> 1160.0993 | L5: =AVERAGEIF('Cleaned Table'!K:K,G5,'Cleaned Table'!C:C) -> 4.7054795 | M5: =_xlfn.XLOOKUP(G5,Location!$P$7:$P$11,Location!$Q$7:$Q$11) -> 55042 | N5: =M5/I5 -> 0.4279461 | S5: Binh Thanh | T5: Ward 17 | U5: =COUNTIF('Cleaned Table'!L:L,Location!T5) -> 1 | V5: =SUMIF('Cleaned Table'!L:L,Location!T5,'Cleaned Table'!D:D) -> 2 | W5: =V5/U5 -> 2
A6: District 7 | B6: 12 | D6: District 7 | E6: 0.029148887 | G6: District 2 | H6: =COUNTIF('Cleaned Table'!K:K,Location!G6) -> 33 | I6: =SUMIF('Cleaned Table'!K:K,Location!G6,'Cleaned Table'!D:D) -> 14747 | J6: =I6/H6 -> 446.87879 | K6: =$K$5 -> 1160.0993 | L6: =AVERAGEIF('Cleaned Table'!K:K,G6,'Cleaned Table'!C:C) -> 4.7272727 | M6: =_xlfn.XLOOKUP(G6,Location!$P$7:$P$11,Location!$Q$7:$Q$11) -> 6625 | N6: =M6/I6 -> 0.44924391 | P6: District | Q6: Sum of No_of_reviews | T6: Ward 19 | U6: =COUNTIF('Cleaned Table'!L:L,Location!T6) -> 5 | V6: =SUMIF('Cleaned Table'!L:L,Location!T6,'Cleaned Table'!D:D) -> 1355 | W6: =V6/U6 -> 271
A7: District 3 | B7: 14 | D7: District 3 | E7: 0.085080759 | G7: District 3 | H7: =COUNTIF('Cleaned Table'!K:K,Location!G7) -> 14 | I7: =SUMIF('Cleaned Table'!K:K,Location!G7,'Cleaned Table'!D:D) -> 13917 | J7: =I7/H7 -> 994.07143 | K7: =$K$5 -> 1160.0993 | L7: =AVERAGEIF('Cleaned Table'!K:K,G7,'Cleaned Table'!C:C) -> 4.6357143 | M7: =_xlfn.XLOOKUP(G7,Location!$P$7:$P$11,Location!$Q$7:$Q$11) -> 10354 | N7: =M7/I7 -> 0.74398218 | P7: Binh Thanh | Q7: 1166 | T7: Ward 22 | U7: =COUNTIF('Cleaned Table'!L:L,Location!T7) -> 3 | V7: =SUMIF('Cleaned Table'!L:L,Location!T7,'Cleaned Table'!D:D) -> 166 | W7: =V7/U7 -> 55.333333
A8: District 2 | B8: 33 | D8: District 2 | E8: 0.090154915 | G8: District 7 | H8: =COUNTIF('Cleaned Table'!K:K,Location!G8) -> 12 | I8: =SUMIF('Cleaned Table'!K:K,Location!G8,'Cleaned Table'!D:D) -> 4768 | J8: =I8/H8 -> 397.33333 | K8: =$K$5 -> 1160.0993 | L8: =AVERAGEIF('Cleaned Table'!K:K,G8,'Cleaned Table'!C:C) -> 4.7083333 | M8: =_xlfn.XLOOKUP(G8,Location!$P$7:$P$11,Location!$Q$7:$Q$11) -> 3270 | N8: =M8/I8 -> 0.68582215 | P8: District 1 | Q8: 55042 | S8: District 1 | T8: Bến Nghé | U8: =COUNTIF('Cleaned Table'!L:L,Location!T8) -> 40 | V8: =SUMIF('Cleaned Table'!L:L,Location!T8,'Cleaned Table'!D:D) -> 45173 | W8: =V8/U8 -> 1129.325
A9: District 1 | B9: 73 | D9: District 1 | E9: 0.78630467 | G9: Binh Thanh | H9: =COUNTIF('Cleaned Table'!K:K,Location!G9) -> 9 | I9: =SUMIF('Cleaned Table'!K:K,Location!G9,'Cleaned Table'!D:D) -> 1523 | J9: =I9/H9 -> 169.22222 | K9: =$K$5 -> 1160.0993 | L9: =AVERAGEIF('Cleaned Table'!K:K,G9,'Cleaned Table'!C:C) -> 4.6 | M9: =_xlfn.XLOOKUP(G9,Location!$P$7:$P$11,Location!$Q$7:$Q$11) -> 1166 | N9: =M9/I9 -> 0.76559422 | P9: District 3 | Q9: 10354 | T9: Bến Thành | U9: =COUNTIF('Cleaned Table'!L:L,Location!T9) -> 7 | V9: =SUMIF('Cleaned Table'!L:L,Location!T9,'Cleaned Table'!D:D) -> 37723 | W9: =V9/U9 -> 5389
A10: Grand Total | B10: 141 | D10: Grand Total | E10: 1 | H10: =SUM(Location!H5:H9) -> 141 | I10: =SUM(Location!I5:I9) -> 163574 | P10: District 7 | Q10: 3270 | T10: Cầu Ông Lãnh | U10: =COUNTIF('Cleaned Table'!L:L,Location!T10) -> 1 | V10: =SUMIF('Cleaned Table'!L:L,Location!T10,'Cleaned Table'!D:D) -> 453 | W10: =V10/U10 -> 453
P11: District 2 | Q11: 6625 | T11: Cô Giang | U11: =COUNTIF('Cleaned Table'!L:L,Location!T11) -> 1 | V11: =SUMIF('Cleaned Table'!L:L,Location!T11,'Cleaned Table'!D:D) -> 641 | W11: =V11/U11 -> 641
T12: Đa Kao | U12: =COUNTIF('Cleaned Table'!L:L,Location!T12) -> 13 | V12: =SUMIF('Cleaned Table'!L:L,Location!T12,'Cleaned Table'!D:D) -> 9068 | W12: =V12/U12 -> 697.53846
T13: Nguyễn Thái Bình | U13: =COUNTIF('Cleaned Table'!L:L,Location!T13) -> 2 | V13: =SUMIF('Cleaned Table'!L:L,Location!T13,'Cleaned Table'!D:D) -> 3054 | W13: =V13/U13 -> 1527
T14: Phạm Ngũ Lão | U14: =COUNTIF('Cleaned Table'!L:L,Location!T14) -> 6 | V14: =SUMIF('Cleaned Table'!L:L,Location!T14,'Cleaned Table'!D:D) -> 28493 | W14: =V14/U14 -> 4748.8333
T15: Tân Định | U15: =COUNTIF('Cleaned Table'!L:L,Location!T15) -> 3 | V15: =SUMIF('Cleaned Table'!L:L,Location!T15,'Cleaned Table'!D:D) -> 4014 | W15: =V15/U15 -> 1338
S16: District 3 | T16: Võ Thị Sáu | U16: =COUNTIF('Cleaned Table'!L:L,Location!T16) -> 11 | V16: =SUMIF('Cleaned Table'!L:L,Location!T16,'Cleaned Table'!D:D) -> 13590 | W16: =V16/U16 -> 1235.4545
T17: Ward 14 | U17: =COUNTIF('Cleaned Table'!L:L,Location!T17) -> 1 | V17: =SUMIF('Cleaned Table'!L:L,Location!T17,'Cleaned Table'!D:D) -> 186 | W17: =V17/U17 -> 186
T18: Ward 11 | U18: =COUNTIF('Cleaned Table'!L:L,Location!T18) -> 1 | V18: =SUMIF('Cleaned Table'!L:L,Location!T18,'Cleaned Table'!D:D) -> 90 | W18: =V18/U18 -> 90
T19: Ward 12 | U19: =COUNTIF('Cleaned Table'!L:L,Location!T19) -> 1 | V19: =SUMIF('Cleaned Table'!L:L,Location!T19,'Cleaned Table'!D:D) -> 51 | W19: =V19/U19 -> 51
S20: District 7 | T20: Tân Hưng | U20: =COUNTIF('Cleaned Table'!L:L,Location!T20) -> 1 | V20: =SUMIF('Cleaned Table'!L:L,Location!T20,'Cleaned Table'!D:D) -> 686 | W20: =V20/U20 -> 686
T21: Tân Phong | U21: =COUNTIF('Cleaned Table'!L:L,Location!T21) -> 4 | V21: =SUMIF('Cleaned Table'!L:L,Location!T21,'Cleaned Table'!D:D) -> 2048 | W21: =V21/U21 -> 512
T22: Tân Phú | U22: =COUNTIF('Cleaned Table'!L:L,Location!T22) -> 5 | V22: =SUMIF('Cleaned Table'!L:L,Location!T22,'Cleaned Table'!D:D) -> 1608 | W22: =V22/U22 -> 321.6
T23: Tân Quy | U23: =COUNTIF('Cleaned Table'!L:L,Location!T23) -> 2 | V23: =SUMIF('Cleaned Table'!L:L,Location!T23,'Cleaned Table'!D:D) -> 426 | W23: =V23/U23 -> 213
S24: District 2 | T24: Thảo Điền | U24: =COUNTIF('Cleaned Table'!L:L,Location!T24) -> 28 | V24: =SUMIF('Cleaned Table'!L:L,Location!T24,'Cleaned Table'!D:D) -> 13473 | W24: =V24/U24 -> 481.17857
T25: An Phú | U25: =COUNTIF('Cleaned Table'!L:L,Location!T25) -> 5 | V25: =SUMIF('Cleaned Table'!L:L,Location!T25,'Cleaned Table'!D:D) -> 1274 | W25: =V25/U25 -> 254.8

Sheet Price Gap
A2: Price range share | F2: Popular price range by district | K2: Popular price range
B4: Column Labels | F4: Count of Restaurant_name | G4: Column Labels | K4: Count of Restaurant_name | M4: Price_bucket
A5: Values | B5: Low | C5: Medium | D5: Premium | F5: Row Labels | G5: Low | H5: Medium | I5: Premium | K5: District | L5: Ward | M5: Low | N5: Medium | O5: Premium | P5: No data
A6: # Listing | B6: 0.15151515 | C6: 0.47727273 | D6: 0.37121212 | F6: District 1 | G6: 6 | H6: 28 | I6: 34 | K6: Binh Thanh | L6: Ward 17 | N6: 1
A7: # Reviews | B7: 0.033984766 | C7: 0.61612248 | D7: 0.34989276 | F7: District 2 | G7: 6 | H7: 17 | I7: 10 | K7: Binh Thanh | L7: Ward 19 | N7: 5
F8: District 3 | G8: 6 | H8: 5 | I8: 3 | K8: Binh Thanh | L8: Ward 22 | M8: 2 | N8: 1
F9: District 7 | H9: 6 | I9: 2 | K9: Binh Thanh Total | M9: 2 | N9: 7
F10: Binh Thanh | G10: 2 | H10: 7 | K10: District 1 | L10: Bến Nghé | M10: 3 | N10: 9 | O10: 25 | P10: 3
F11: Grand Total | G11: 20 | H11: 63 | I11: 49 | K11: District 1 | L11: Bến Thành | N11: 6 | O11: 1
K12: District 1 | L12: Cầu Ông Lãnh | N12: 1
K13: District 1 | L13: Cô Giang | N13: 1
K14: District 1 | L14: Đa Kao | M14: 2 | N14: 5 | O14: 4 | P14: 2
K15: District 1 | L15: Nguyễn Thái Bình | N15: 1 | O15: 1
K16: District 1 | L16: Phạm Ngũ Lão | M16: 1 | N16: 3 | O16: 2
K17: District 1 | L17: Tân Định | N17: 2 | O17: 1
K18: District 1 Total | M18: 6 | N18: 28 | O18: 34 | P18: 5
K19: District 3 | L19: Võ Thị Sáu | M19: 3 | N19: 5 | O19: 3
K20: District 3 | L20: Ward 14 | M20: 1
K21: District 3 | L21: Ward 11 | M21: 1
K22: District 3 | L22: Ward 12 | M22: 1
K23: District 3 Total | M23: 6 | N23: 5 | O23: 3
K24: District 7 | L24: Tân Hưng | N24: 1
K25: District 7 | L25: Tân Phong | N25: 2 | P25: 2
K26: District 7 | L26: Tân Phú | N26: 2 | O26: 2 | P26: 1
K27: District 7 | L27: Tân Quy | N27: 1 | P27: 1
K28: District 7 Total | N28: 6 | O28: 2 | P28: 4
K29: District 2 | L29: An Phú | M29: 3 | N29: 2
K30: District 2 | L30: Thảo Điền | M30: 3 | N30: 15 | O30: 10
K31: District 2 Total | M31: 6 | N31: 17 | O31: 10
K32: Grand Total | M32: 20 | N32: 63 | O32: 49 | P32: 9

Sheet Concept
A2: # Restaurant & review by restaurant concept | E2: # restaurant per district by restaurant concept | M2: Price range distribution by restaurant concept | S2: Restaurant quantity by café options | V2: Restaurant quantity breakdown by café options & district | Z2: Price range distribution by Café options
A4: Row Labels | B4: % reviews | C4: % restaurant | E4: Count of Restaurant_name | F4: Column Labels | M4: Count of Restaurant_name | N4: Column Labels | S4: Row Labels | T4: Count of Restaurant_name | V4: Count of Restaurant_name | W4: Column Labels | Z4: Count of Restaurant_name | AA4: Column Labels
A5: Buffet / hotpot vegetarian | B5: 0.0050619292 | C5: 0.021276596 | E5: Row Labels | F5: District 1 | G5: District 2 | H5: District 3 | I5: District 7 | J5: Binh Thanh | K5: Grand Total | M5: Row Labels | N5: Low | O5: Medium | P5: Premium | Q5: Grand Total | S5: No | T5: 0.78014184 | V5: Row Labels | W5: No | X5: Yes | Z5: Row Labels | AA5: No | AB5: Yes | AC5: Grand Total
A6: Quick-service / noodle / banh mi vegetarian | B6: 0.11900424 | C6: 0.042553191 | E6: Vegetarian bistro / casual dining | F6: 37 | G6: 12 | H6: 2 | I6: 3 | J6: 1 | K6: 55 | M6: Vegetarian bistro / casual dining | N6: 5 | O6: 19 | P6: 24 | Q6: 48 | S6: Yes | T6: 0.21985816 | V6: Binh Thanh | W6: 0.66666667 | X6: 0.33333333 | Z6: Low | AA6: 17 | AB6: 3 | AC6: 20
A7: Local Vietnamese vegetarian | B7: 0.048320638 | C7: 0.092198582 | E7: Modern vegan / plant-based | F7: 12 | G7: 9 | H7: 4 | I7: 5 | J7: 4 | K7: 34 | M7: Modern vegan / plant-based | N7: 5 | O7: 20 | P7: 9 | Q7: 34 | S7: Grand Total | T7: 1 | V7: District 1 | W7: 0.8630137 | X7: 0.1369863 | Z7: Medium | AA7: 48 | AB7: 15 | AC7: 63
A8: Vegetarian cafe / light dining | B8: 0.13207478 | C8: 0.21276596 | E8: Vegetarian cafe / light dining | F8: 9 | G8: 9 | H8: 5 | I8: 4 | J8: 3 | K8: 30 | M8: Vegetarian cafe / light dining | N8: 3 | O8: 14 | P8: 11 | Q8: 28 | V8: District 3 | W8: 0.64285714 | X8: 0.35714286 | Z8: Premium | AA8: 38 | AB8: 11 | AC8: 49
A9: Modern vegan / plant-based | B9: 0.25407461 | C9: 0.24113475 | E9: Local Vietnamese vegetarian | F9: 8 | G9: 2 | H9: 2 | J9: 1 | K9: 13 | M9: Local Vietnamese vegetarian | N9: 4 | O9: 5 | P9: 4 | Q9: 13 | V9: District 7 | W9: 0.66666667 | X9: 0.33333333 | Z9: No data | AA9: 7 | AB9: 2 | AC9: 9
A10: Vegetarian bistro / casual dining | B10: 0.4414638 | C10: 0.39007092 | E10: Quick-service / noodle / banh mi vegetarian | F10: 4 | G10: 1 | H10: 1 | K10: 6 | M10: Quick-service / noodle / banh mi vegetarian | N10: 2 | O10: 4 | Q10: 6 | V10: District 2 | W10: 0.72727273 | X10: 0.27272727 | Z10: Grand Total | AA10: 110 | AB10: 31 | AC10: 141
A11: Grand Total | B11: 1 | C11: 1 | E11: Buffet / hotpot vegetarian | F11: 3 | K11: 3 | M11: Buffet / hotpot vegetarian | N11: 1 | O11: 1 | P11: 1 | Q11: 3 | V11: Grand Total | W11: 0.78014184 | X11: 0.21985816
E12: Grand Total | F12: 73 | G12: 33 | H12: 14 | I12: 12 | J12: 9 | K12: 141 | M12: Grand Total | N12: 20 | O12: 63 | P12: 49 | Q12: 132

Sheet Others
A2: Rating vs Number of Reviews | D2: Restaurant Opening hour | G2: Opening hour by district | N2: Restaurant Opening hour
A4: Mean | B4: =AVERAGE('Cleaned Table'!C:C) -> 4.6971631 | D4: Row Labels | E4: Count of Restaurant_name | G4: Count of Restaurant_name | H4: Column Labels | N4: Row Labels | O4: Count of Restaurant_name
A5: Mode | B5: =_xlfn.MODE.SNGL('Cleaned Table'!C:C) -> 4.9 | D5: Morning | E5: 0.77011494 | G5: Row Labels | H5: Morning | I5: Lunch | J5: Afternoon | K5: Night | L5: No data | N5: Morning | O5: 0.77011494
A6: Weighted rating | B6: =SUMPRODUCT(A9:A18,B9:B18)/SUM(B9:B18) -> 4.7153032 | D6: Lunch | E6: 0.091954023 | G6: Binh Thanh | H6: 5 | L6: 4 | N6: 0.3125 | O6: 0.011494253
D7: Afternoon | E7: 0.11494253 | G7: District 1 | H7: 30 | I7: 4 | J7: 8 | K7: 1 | L7: 30 | N7: 0.32291667 | O7: 0.011494253
A8: Row Labels | B8: Sum of No_of_reviews | D8: Night | E8: 0.022988506 | G8: District 3 | H8: 9 | J8: 1 | K8: 1 | L8: 3 | N8: 0.33333333 | O8: 0.11494253
A9: 4.1 | B9: 59 | D9: Grand Total | E9: 1 | G9: District 7 | H9: 5 | I9: 1 | L9: 6 | N9: 0.35416667 | O9: 0.08045977
A10: 4.2 | B10: 276 | G10: District 2 | H10: 18 | I10: 3 | J10: 1 | L10: 11 | N10: 0.375 | O10: 0.17241379
A11: 4.3 | B11: 17300 | G11: Grand Total | H11: 67 | I11: 8 | J11: 10 | K11: 2 | L11: 54 | N11: 0.39583333 | O11: 0.022988506
A12: 4.4 | B12: 8656 | N12: 0.41666667 | O12: 0.25287356
A13: 4.5 | B13: 13614 | N13: 0.4375 | O13: 0.10344828
A14: 4.6 | B14: 17307 | N14: Lunch | O14: 0.091954023
A15: 4.7 | B15: 11244 | N15: 0.45833333 | O15: 0.08045977
A16: 4.8 | B16: 23928 | N16: 0.47916667 | O16: 0.011494253
A17: 4.9 | B17: 71029 | N17: Afternoon | O17: 0.11494253
A18: 5 | B18: 161 | N18: 0.66666667 | O18: 0.022988506
A19: Grand Total | B19: 163574 | N19: 0.6875 | O19: 0.011494253
N20: 0.70833333 | O20: 0.045977011
N21: 0.72916667 | O21: 0.034482759
N22: Night | O22: 0.022988506
N23: 0.75 | O23: 0.022988506
N24: Grand Total | O24: 1

Sheet Scoring model_input
A1: Scenario | B1: District | C1: Restaurants in bucket | D1: Reviews in bucket | E1: Reviews / restaurant | F1: Price restaurant share | G1: Price review share | H1: Opportunity gap | I1: Customer segment fit | J1: Restaurant concept fit | K1: Notes
A2: Medium | B2: District 1 | C2: =COUNTIFS('Cleaned Table'!$M:$M,'Scoring model_input'!A2,'Cleaned Table'!$K:$K,'Scoring model_input'!B2) -> 28 | D2: =SUMIFS('Cleaned Table'!$D:$D,'Cleaned Table'!$M:$M,'Scoring model_input'!A2,'Cleaned Table'!$K:$K,'Scoring model_input'!B2) -> 83237 | E2: =D2/C2 -> 2972.75 | F2: =C2/COUNTIF('Cleaned Table'!$K:$K,'Scoring model_input'!B2) -> 0.38356164 | G2: =D2/SUMIF('Cleaned Table'!$K:$K,'Scoring model_input'!B2,'Cleaned Table'!$D:$D) -> 0.64715944 | H2: =G2-F2 -> 0.2635978 | I2: 90 | J2: 80 | K2: Strongest proven demand; use only with clear differentiation due to competition.
A3: Medium | B3: District 2 | C3: =COUNTIFS('Cleaned Table'!$M:$M,'Scoring model_input'!A3,'Cleaned Table'!$K:$K,'Scoring model_input'!B3) -> 17 | D3: =SUMIFS('Cleaned Table'!$D:$D,'Cleaned Table'!$M:$M,'Scoring model_input'!A3,'Cleaned Table'!$K:$K,'Scoring model_input'!B3) -> 5357 | E3: =D3/C3 -> 315.11765 | F3: =C3/COUNTIF('Cleaned Table'!$K:$K,'Scoring model_input'!B3) -> 0.51515152 | G3: =D3/SUMIF('Cleaned Table'!$K:$K,'Scoring model_input'!B3,'Cleaned Table'!$D:$D) -> 0.36326032 | H3: =G3-F3 -> -0.15189119 | I3: 95 | J3: 70 | K3: Good expat fit; medium bistro/cafe can work if positioned more lifestyle-led.
A4: Medium | B4: District 3 | C4: =COUNTIFS('Cleaned Table'!$M:$M,'Scoring model_input'!A4,'Cleaned Table'!$K:$K,'Scoring model_input'!B4) -> 5 | D4: =SUMIFS('Cleaned Table'!$D:$D,'Cleaned Table'!$M:$M,'Scoring model_input'!A4,'Cleaned Table'!$K:$K,'Scoring model_input'!B4) -> 5354 | E4: =D4/C4 -> 1070.8 | F4: =C4/COUNTIF('Cleaned Table'!$K:$K,'Scoring model_input'!B4) -> 0.35714286 | G4: =D4/SUMIF('Cleaned Table'!$K:$K,'Scoring model_input'!B4,'Cleaned Table'!$D:$D) -> 0.38470935 | H4: =G4-F4 -> 0.027566491 | I4: 75 | J4: 90 | K4: Smaller base but strong reviews per restaurant; good alternative to D1.
A5: Medium | B5: District 7 | C5: =COUNTIFS('Cleaned Table'!$M:$M,'Scoring model_input'!A5,'Cleaned Table'!$K:$K,'Scoring model_input'!B5) -> 6 | D5: =SUMIFS('Cleaned Table'!$D:$D,'Cleaned Table'!$M:$M,'Scoring model_input'!A5,'Cleaned Table'!$K:$K,'Scoring model_input'!B5) -> 2605 | E5: =D5/C5 -> 434.16667 | F5: =C5/COUNTIF('Cleaned Table'!$K:$K,'Scoring model_input'!B5) -> 0.5 | G5: =D5/SUMIF('Cleaned Table'!$K:$K,'Scoring model_input'!B5,'Cleaned Table'!$D:$D) -> 0.54635067 | H5: =G5-F5 -> 0.046350671 | I5: 85 | J5: 90 | K5: Balanced medium opportunity for expat/residential market.
A6: Medium | B6: Binh Thanh | C6: =COUNTIFS('Cleaned Table'!$M:$M,'Scoring model_input'!A6,'Cleaned Table'!$K:$K,'Scoring model_input'!B6) -> 7 | D6: =SUMIFS('Cleaned Table'!$D:$D,'Cleaned Table'!$M:$M,'Scoring model_input'!A6,'Cleaned Table'!$K:$K,'Scoring model_input'!B6) -> 1400 | E6: =D6/C6 -> 200 | F6: =C6/COUNTIF('Cleaned Table'!$K:$K,'Scoring model_input'!B6) -> 0.77777778 | G6: =D6/SUMIF('Cleaned Table'!$K:$K,'Scoring model_input'!B6,'Cleaned Table'!$D:$D) -> 0.91923835 | H6: =G6-F6 -> 0.14146057 | I6: 80 | J6: 85 | K6: Medium price is the dominant bucket, but total demand is still smaller.
A7: Premium | B7: District 1 | C7: =COUNTIFS('Cleaned Table'!$M:$M,'Scoring model_input'!A7,'Cleaned Table'!$K:$K,'Scoring model_input'!B7) -> 34 | D7: =SUMIFS('Cleaned Table'!$D:$D,'Cleaned Table'!$M:$M,'Scoring model_input'!A7,'Cleaned Table'!$K:$K,'Scoring model_input'!B7) -> 39415 | E7: =D7/C7 -> 1159.2647 | F7: =C7/COUNTIF('Cleaned Table'!$K:$K,'Scoring model_input'!B7) -> 0.46575342 | G7: =D7/SUMIF('Cleaned Table'!$K:$K,'Scoring model_input'!B7,'Cleaned Table'!$D:$D) -> 0.30644773 | H7: =G7-F7 -> -0.1593057 | I7: 90 | J7: 92 | K7: Premium demand exists, but market is highly saturated.
A8: Premium | B8: District 2 | C8: =COUNTIFS('Cleaned Table'!$M:$M,'Scoring model_input'!A8,'Cleaned Table'!$K:$K,'Scoring model_input'!B8) -> 10 | D8: =SUMIFS('Cleaned Table'!$D:$D,'Cleaned Table'!$M:$M,'Scoring model_input'!A8,'Cleaned Table'!$K:$K,'Scoring model_input'!B8) -> 7766 | E8: =D8/C8 -> 776.6 | F8: =C8/COUNTIF('Cleaned Table'!$K:$K,'Scoring model_input'!B8) -> 0.3030303 | G8: =D8/SUMIF('Cleaned Table'!$K:$K,'Scoring model_input'!B8,'Cleaned Table'!$D:$D) -> 0.52661558 | H8: =G8-F8 -> 0.22358528 | I8: 95 | J8: 92 | K8: Best premium white-space: strong expat fit and review share exceeds supply share.
A9: Premium | B9: District 3 | C9: =COUNTIFS('Cleaned Table'!$M:$M,'Scoring model_input'!A9,'Cleaned Table'!$K:$K,'Scoring model_input'!B9) -> 3 | D9: =SUMIFS('Cleaned Table'!$D:$D,'Cleaned Table'!$M:$M,'Scoring model_input'!A9,'Cleaned Table'!$K:$K,'Scoring model_input'!B9) -> 7482 | E9: =D9/C9 -> 2494 | F9: =C9/COUNTIF('Cleaned Table'!$K:$K,'Scoring model_input'!B9) -> 0.21428571 | G9: =D9/SUMIF('Cleaned Table'!$K:$K,'Scoring model_input'!B9,'Cleaned Table'!$D:$D) -> 0.53761587 | H9: =G9-F9 -> 0.32333015 | I9: 55 | J9: 85 | K9: Strong premium review signal, but lower strategic fit than D2 for expat/lifestyle positioning; validate audience mix and site economics.
A10: Premium | B10: District 7 | C10: =COUNTIFS('Cleaned Table'!$M:$M,'Scoring model_input'!A10,'Cleaned Table'!$K:$K,'Scoring model_input'!B10) -> 2 | D10: =SUMIFS('Cleaned Table'!$D:$D,'Cleaned Table'!$M:$M,'Scoring model_input'!A10,'Cleaned Table'!$K:$K,'Scoring model_input'!B10) -> 964 | E10: =D10/C10 -> 482 | F10: =C10/COUNTIF('Cleaned Table'!$K:$K,'Scoring model_input'!B10) -> 0.16666667 | G10: =D10/SUMIF('Cleaned Table'!$K:$K,'Scoring model_input'!B10,'Cleaned Table'!$D:$D) -> 0.20218121 | H10: =G10-F10 -> 0.035514541 | I10: 75 | J10: 80 | K10: Lower competition, but premium demand is smaller than D1/D2/D3.
A11: Premium | B11: Binh Thanh | C11: =COUNTIFS('Cleaned Table'!$M:$M,'Scoring model_input'!A11,'Cleaned Table'!$K:$K,'Scoring model_input'!B11) -> 0 | D11: =SUMIFS('Cleaned Table'!$D:$D,'Cleaned Table'!$M:$M,'Scoring model_input'!A11,'Cleaned Table'!$K:$K,'Scoring model_input'!B11) -> 0 | E11: =IFERROR(D11/C11,0) -> 0 | F11: =C11/COUNTIF('Cleaned Table'!$K:$K,'Scoring model_input'!B11) -> 0 | G11: =D11/SUMIF('Cleaned Table'!$K:$K,'Scoring model_input'!B11,'Cleaned Table'!$D:$D) -> 0 | H11: =G11-F11 -> 0 | I11: 65 | J11: 30 | K11: No premium evidence in current shortlist.

Sheet Scoring model_result
A1: Scenario | B1: District | C1: Restaurants | D1: Reviews | E1: Reviews / restaurant | F1: Price restaurant share | G1: Price review share | H1: Opportunity gap | I1: Demand Strength Score | J1: Competition Intensity | K1: Gap Score | L1: Price Fit Score | M1: Customer Fit Score | N1: Concept Fit Score | O1: Final Weighted Score | P1: Rank | Q1: Interpretation
A2: ='[1]Input Metrics'!A10 -> Medium | B2: ='[1]Input Metrics'!B10 -> District 1 | C2: ='Scoring model_input'!C2 -> 28 | D2: ='Scoring model_input'!D2 -> 83237 | E2: ='Scoring model_input'!E2 -> 2972.75 | F2: ='Scoring model_input'!F2 -> 0.38356164 | G2: ='Scoring model_input'!G2 -> 0.64715944 | H2: ='Scoring model_input'!H2 -> 0.2635978 | I2: =IFERROR(0.6*((D2-_xlfn.MINIFS($D$2:$D$11,$A$2:$A$11,$A2))/(_xlfn.MAXIFS($D$2:$D$11,$A$2:$A$11,$A2)-_xlfn.MINIFS($D$2:$D$11,$A$2:$A$11,$A2))*100)+0.4*((E2-_xlfn.MINIFS($E$2:$E$11,$A$2:$A$11,$A2))/(_xlfn.MAXIFS($E$2:$E$11,$A$2:$A$11,$A2)-_xlfn.MINIFS($E$2:$E$11,$A$2:$A$11,$A2))*100),0) -> 100 | J2: =IF(D2=0,45,IFERROR((_xlfn.MAXIFS($C$2:$C$11,$A$2:$A$11,$A2)-C2)/(_xlfn.MAXIFS($C$2:$C$11,$A$2:$A$11,$A2)-_xlfn.MINIFS($C$2:$C$11,$A$2:$A$11,$A2))*100,0)) -> 0 | K2: =IFERROR((H2-_xlfn.MINIFS($H$2:$H$11,$A$2:$A$11,$A2))/(_xlfn.MAXIFS($H$2:$H$11,$A$2:$A$11,$A2)-_xlfn.MINIFS($H$2:$H$11,$A$2:$A$11,$A2))*100,0) -> 100 | L2: =((F2*100)*0.5)+((G2*100)*0.5) -> 51.536054 | M2: ='[1]Input Metrics'!J10 -> 90 | N2: ='[1]Input Metrics'!K10 -> 80 | O2: =I2*VLOOKUP($A2,$A$16:$G$18,2,FALSE)+J2*VLOOKUP($A2,$A$16:$G$18,3,FALSE)+K2*VLOOKUP($A2,$A$16:$G$18,4,FALSE)+L2*VLOOKUP($A2,$A$16:$G$18,5,FALSE)+M2*VLOOKUP($A2,$A$16:$G$18,6,FALSE)+N2*VLOOKUP($A2,$A$16:$G$18,7,FALSE) -> 74.230408 | P2: =COUNTIFS($A$2:$A$11,A2,$O$2:$O$11,">"&O2)+1 -> 1 | Q2: =IF(P2=1,"Best option for "&A2,IF(P2=2,"Runner-up","Lower priority / validate further")) -> Best option for Medium
A3: ='[1]Input Metrics'!A11 -> Medium | B3: ='[1]Input Metrics'!B11 -> District 2 | C3: ='Scoring model_input'!C3 -> 17 | D3: ='Scoring model_input'!D3 -> 5357 | E3: ='Scoring model_input'!E3 -> 315.11765 | F3: ='Scoring model_input'!F3 -> 0.51515152 | G3: ='Scoring model_input'!G3 -> 0.36326032 | H3: ='Scoring model_input'!H3 -> -0.15189119 | I3: =IFERROR(0.6*((D3-_xlfn.MINIFS($D$2:$D$11,$A$2:$A$11,$A3))/(_xlfn.MAXIFS($D$2:$D$11,$A$2:$A$11,$A3)-_xlfn.MINIFS($D$2:$D$11,$A$2:$A$11,$A3))*100)+0.4*((E3-_xlfn.MINIFS($E$2:$E$11,$A$2:$A$11,$A3))/(_xlfn.MAXIFS($E$2:$E$11,$A$2:$A$11,$A3)-_xlfn.MINIFS($E$2:$E$11,$A$2:$A$11,$A3))*100),0) -> 4.5618327 | J3: =IF(D3=0,45,IFERROR((_xlfn.MAXIFS($C$2:$C$11,$A$2:$A$11,$A3)-C3)/(_xlfn.MAXIFS($C$2:$C$11,$A$2:$A$11,$A3)-_xlfn.MINIFS($C$2:$C$11,$A$2:$A$11,$A3))*100,0)) -> 47.826087 | K3: =IFERROR((H3-_xlfn.MINIFS($H$2:$H$11,$A$2:$A$11,$A3))/(_xlfn.MAXIFS($H$2:$H$11,$A$2:$A$11,$A3)-_xlfn.MINIFS($H$2:$H$11,$A$2:$A$11,$A3))*100,0) -> 0 | L3: =((F3*100)*0.5)+((G3*100)*0.5) -> 43.920592 | M3: ='[1]Input Metrics'!J11 -> 95 | N3: ='[1]Input Metrics'!K11 -> 70 | O3: =I3*VLOOKUP($A3,$A$16:$G$18,2,FALSE)+J3*VLOOKUP($A3,$A$16:$G$18,3,FALSE)+K3*VLOOKUP($A3,$A$16:$G$18,4,FALSE)+L3*VLOOKUP($A3,$A$16:$G$18,5,FALSE)+M3*VLOOKUP($A3,$A$16:$G$18,6,FALSE)+N3*VLOOKUP($A3,$A$16:$G$18,7,FALSE) -> 36.15246 | P3: =COUNTIFS($A$2:$A$11,A3,$O$2:$O$11,">"&O3)+1 -> 5 | Q3: =IF(P3=1,"Best option for "&A3,IF(P3=2,"Runner-up","Lower priority / validate further")) -> Lower priority / validate further
A4: ='[1]Input Metrics'!A12 -> Medium | B4: ='[1]Input Metrics'!B12 -> District 3 | C4: ='Scoring model_input'!C4 -> 5 | D4: ='Scoring model_input'!D4 -> 5354 | E4: ='Scoring model_input'!E4 -> 1070.8 | F4: ='Scoring model_input'!F4 -> 0.35714286 | G4: ='Scoring model_input'!G4 -> 0.38470935 | H4: ='Scoring model_input'!H4 -> 0.027566491 | I4: =IFERROR(0.6*((D4-_xlfn.MINIFS($D$2:$D$11,$A$2:$A$11,$A4))/(_xlfn.MAXIFS($D$2:$D$11,$A$2:$A$11,$A4)-_xlfn.MINIFS($D$2:$D$11,$A$2:$A$11,$A4))*100)+0.4*((E4-_xlfn.MINIFS($E$2:$E$11,$A$2:$A$11,$A4))/(_xlfn.MAXIFS($E$2:$E$11,$A$2:$A$11,$A4)-_xlfn.MINIFS($E$2:$E$11,$A$2:$A$11,$A4))*100),0) -> 15.461191 | J4: =IF(D4=0,45,IFERROR((_xlfn.MAXIFS($C$2:$C$11,$A$2:$A$11,$A4)-C4)/(_xlfn.MAXIFS($C$2:$C$11,$A$2:$A$11,$A4)-_xlfn.MINIFS($C$2:$C$11,$A$2:$A$11,$A4))*100,0)) -> 100 | K4: =IFERROR((H4-_xlfn.MINIFS($H$2:$H$11,$A$2:$A$11,$A4))/(_xlfn.MAXIFS($H$2:$H$11,$A$2:$A$11,$A4)-_xlfn.MINIFS($H$2:$H$11,$A$2:$A$11,$A4))*100,0) -> 43.191923 | L4: =((F4*100)*0.5)+((G4*100)*0.5) -> 37.09261 | M4: ='[1]Input Metrics'!J12 -> 75 | N4: ='[1]Input Metrics'!K12 -> 90 | O4: =I4*VLOOKUP($A4,$A$16:$G$18,2,FALSE)+J4*VLOOKUP($A4,$A$16:$G$18,3,FALSE)+K4*VLOOKUP($A4,$A$16:$G$18,4,FALSE)+L4*VLOOKUP($A4,$A$16:$G$18,5,FALSE)+M4*VLOOKUP($A4,$A$16:$G$18,6,FALSE)+N4*VLOOKUP($A4,$A$16:$G$18,7,FALSE) -> 53.317574 | P4: =COUNTIFS($A$2:$A$11,A4,$O$2:$O$11,">"&O4)+1 -> 4 | Q4: =IF(P4=1,"Best option for "&A4,IF(P4=2,"Runner-up","Lower priority / validate further")) -> Lower priority / validate further
A5: ='[1]Input Metrics'!A13 -> Medium | B5: ='[1]Input Metrics'!B13 -> District 7 | C5: ='Scoring model_input'!C5 -> 6 | D5: ='Scoring model_input'!D5 -> 2605 | E5: ='Scoring model_input'!E5 -> 434.16667 | F5: ='Scoring model_input'!F5 -> 0.5 | G5: ='Scoring model_input'!G5 -> 0.54635067 | H5: ='Scoring model_input'!H5 -> 0.046350671 | I5: =IFERROR(0.6*((D5-_xlfn.MINIFS($D$2:$D$11,$A$2:$A$11,$A5))/(_xlfn.MAXIFS($D$2:$D$11,$A$2:$A$11,$A5)-_xlfn.MINIFS($D$2:$D$11,$A$2:$A$11,$A5))*100)+0.4*((E5-_xlfn.MINIFS($E$2:$E$11,$A$2:$A$11,$A5))/(_xlfn.MAXIFS($E$2:$E$11,$A$2:$A$11,$A5)-_xlfn.MINIFS($E$2:$E$11,$A$2:$A$11,$A5))*100),0) -> 4.2615779 | J5: =IF(D5=0,45,IFERROR((_xlfn.MAXIFS($C$2:$C$11,$A$2:$A$11,$A5)-C5)/(_xlfn.MAXIFS($C$2:$C$11,$A$2:$A$11,$A5)-_xlfn.MINIFS($C$2:$C$11,$A$2:$A$11,$A5))*100,0)) -> 95.652174 | K5: =IFERROR((H5-_xlfn.MINIFS($H$2:$H$11,$A$2:$A$11,$A5))/(_xlfn.MAXIFS($H$2:$H$11,$A$2:$A$11,$A5)-_xlfn.MINIFS($H$2:$H$11,$A$2:$A$11,$A5))*100,0) -> 47.712904 | L5: =((F5*100)*0.5)+((G5*100)*0.5) -> 52.317534 | M5: ='[1]Input Metrics'!J13 -> 85 | N5: ='[1]Input Metrics'!K13 -> 90 | O5: =I5*VLOOKUP($A5,$A$16:$G$18,2,FALSE)+J5*VLOOKUP($A5,$A$16:$G$18,3,FALSE)+K5*VLOOKUP($A5,$A$16:$G$18,4,FALSE)+L5*VLOOKUP($A5,$A$16:$G$18,5,FALSE)+M5*VLOOKUP($A5,$A$16:$G$18,6,FALSE)+N5*VLOOKUP($A5,$A$16:$G$18,7,FALSE) -> 54.553431 | P5: =COUNTIFS($A$2:$A$11,A5,$O$2:$O$11,">"&O5)+1 -> 3 | Q5: =IF(P5=1,"Best option for "&A5,IF(P5=2,"Runner-up","Lower priority / validate further")) -> Lower priority / validate further
A6: ='[1]Input Metrics'!A14 -> Medium | B6: ='[1]Input Metrics'!B14 -> Binh Thanh | C6: ='Scoring model_input'!C6 -> 7 | D6: ='Scoring model_input'!D6 -> 1400 | E6: ='Scoring model_input'!E6 -> 200 | F6: ='Scoring model_input'!F6 -> 0.77777778 | G6: ='Scoring model_input'!G6 -> 0.91923835 | H6: ='Scoring model_input'!H6 -> 0.14146057 | I6: =IFERROR(0.6*((D6-_xlfn.MINIFS($D$2:$D$11,$A$2:$A$11,$A6))/(_xlfn.MAXIFS($D$2:$D$11,$A$2:$A$11,$A6)-_xlfn.MINIFS($D$2:$D$11,$A$2:$A$11,$A6))*100)+0.4*((E6-_xlfn.MINIFS($E$2:$E$11,$A$2:$A$11,$A6))/(_xlfn.MAXIFS($E$2:$E$11,$A$2:$A$11,$A6)-_xlfn.MINIFS($E$2:$E$11,$A$2:$A$11,$A6))*100),0) -> 0 | J6: =IF(D6=0,45,IFERROR((_xlfn.MAXIFS($C$2:$C$11,$A$2:$A$11,$A6)-C6)/(_xlfn.MAXIFS($C$2:$C$11,$A$2:$A$11,$A6)-_xlfn.MINIFS($C$2:$C$11,$A$2:$A$11,$A6))*100,0)) -> 91.304348 | K6: =IFERROR((H6-_xlfn.MINIFS($H$2:$H$11,$A$2:$A$11,$A6))/(_xlfn.MAXIFS($H$2:$H$11,$A$2:$A$11,$A6)-_xlfn.MINIFS($H$2:$H$11,$A$2:$A$11,$A6))*100,0) -> 70.603979 | L6: =((F6*100)*0.5)+((G6*100)*0.5) -> 84.850806 | M6: ='[1]Input Metrics'!J14 -> 80 | N6: ='[1]Input Metrics'!K14 -> 85 | O6: =I6*VLOOKUP($A6,$A$16:$G$18,2,FALSE)+J6*VLOOKUP($A6,$A$16:$G$18,3,FALSE)+K6*VLOOKUP($A6,$A$16:$G$18,4,FALSE)+L6*VLOOKUP($A6,$A$16:$G$18,5,FALSE)+M6*VLOOKUP($A6,$A$16:$G$18,6,FALSE)+N6*VLOOKUP($A6,$A$16:$G$18,7,FALSE) -> 61.044069 | P6: =COUNTIFS($A$2:$A$11,A6,$O$2:$O$11,">"&O6)+1 -> 2 | Q6: =IF(P6=1,"Best option for "&A6,IF(P6=2,"Runner-up","Lower priority / validate further")) -> Runner-up
A7: ='[1]Input Metrics'!A15 -> Premium | B7: ='[1]Input Metrics'!B15 -> District 1 | C7: ='Scoring model_input'!C7 -> 34 | D7: ='Scoring model_input'!D7 -> 39415 | E7: ='Scoring model_input'!E7 -> 1159.2647 | F7: ='Scoring model_input'!F7 -> 0.46575342 | G7: ='Scoring model_input'!G7 -> 0.30644773 | H7: ='Scoring model_input'!H7 -> -0.1593057 | I7: =IFERROR(0.6*((D7-_xlfn.MINIFS($D$2:$D$11,$A$2:$A$11,$A7))/(_xlfn.MAXIFS($D$2:$D$11,$A$2:$A$11,$A7)-_xlfn.MINIFS($D$2:$D$11,$A$2:$A$11,$A7))*100)+0.4*((E7-_xlfn.MINIFS($E$2:$E$11,$A$2:$A$11,$A7))/(_xlfn.MAXIFS($E$2:$E$11,$A$2:$A$11,$A7)-_xlfn.MINIFS($E$2:$E$11,$A$2:$A$11,$A7))*100),0) -> 78.592858 | J7: =IF(D7=0,45,IFERROR((_xlfn.MAXIFS($C$2:$C$11,$A$2:$A$11,$A7)-C7)/(_xlfn.MAXIFS($C$2:$C$11,$A$2:$A$11,$A7)-_xlfn.MINIFS($C$2:$C$11,$A$2:$A$11,$A7))*100,0)) -> 0 | K7: =IFERROR((H7-_xlfn.MINIFS($H$2:$H$11,$A$2:$A$11,$A7))/(_xlfn.MAXIFS($H$2:$H$11,$A$2:$A$11,$A7)-_xlfn.MINIFS($H$2:$H$11,$A$2:$A$11,$A7))*100,0) -> 0 | L7: =((F7*100)*0.5)+((G7*100)*0.5) -> 38.610058 | M7: ='[1]Input Metrics'!J15 -> 90 | N7: ='[1]Input Metrics'!K15 -> 92 | O7: =I7*VLOOKUP($A7,$A$16:$G$18,2,FALSE)+J7*VLOOKUP($A7,$A$16:$G$18,3,FALSE)+K7*VLOOKUP($A7,$A$16:$G$18,4,FALSE)+L7*VLOOKUP($A7,$A$16:$G$18,5,FALSE)+M7*VLOOKUP($A7,$A$16:$G$18,6,FALSE)+N7*VLOOKUP($A7,$A$16:$G$18,7,FALSE) -> 55.140583 | P7: =COUNTIFS($A$2:$A$11,A7,$O$2:$O$11,">"&O7)+1 -> 3 | Q7: =IF(P7=1,"Best option for "&A7,IF(P7=2,"Runner-up","Lower priority / validate further")) -> Lower priority / validate further
A8: ='[1]Input Metrics'!A16 -> Premium | B8: ='[1]Input Metrics'!B16 -> District 2 | C8: ='Scoring model_input'!C8 -> 10 | D8: ='Scoring model_input'!D8 -> 7766 | E8: ='Scoring model_input'!E8 -> 776.6 | F8: ='Scoring model_input'!F8 -> 0.3030303 | G8: ='Scoring model_input'!G8 -> 0.52661558 | H8: ='Scoring model_input'!H8 -> 0.22358528 | I8: =IFERROR(0.6*((D8-_xlfn.MINIFS($D$2:$D$11,$A$2:$A$11,$A8))/(_xlfn.MAXIFS($D$2:$D$11,$A$2:$A$11,$A8)-_xlfn.MINIFS($D$2:$D$11,$A$2:$A$11,$A8))*100)+0.4*((E8-_xlfn.MINIFS($E$2:$E$11,$A$2:$A$11,$A8))/(_xlfn.MAXIFS($E$2:$E$11,$A$2:$A$11,$A8)-_xlfn.MINIFS($E$2:$E$11,$A$2:$A$11,$A8))*100),0) -> 24.277388 | J8: =IF(D8=0,45,IFERROR((_xlfn.MAXIFS($C$2:$C$11,$A$2:$A$11,$A8)-C8)/(_xlfn.MAXIFS($C$2:$C$11,$A$2:$A$11,$A8)-_xlfn.MINIFS($C$2:$C$11,$A$2:$A$11,$A8))*100,0)) -> 70.588235 | K8: =IFERROR((H8-_xlfn.MINIFS($H$2:$H$11,$A$2:$A$11,$A8))/(_xlfn.MAXIFS($H$2:$H$11,$A$2:$A$11,$A8)-_xlfn.MINIFS($H$2:$H$11,$A$2:$A$11,$A8))*100,0) -> 79.333307 | L8: =((F8*100)*0.5)+((G8*100)*0.5) -> 41.482294 | M8: ='[1]Input Metrics'!J16 -> 95 | N8: ='[1]Input Metrics'!K16 -> 92 | O8: =I8*VLOOKUP($A8,$A$16:$G$18,2,FALSE)+J8*VLOOKUP($A8,$A$16:$G$18,3,FALSE)+K8*VLOOKUP($A8,$A$16:$G$18,4,FALSE)+L8*VLOOKUP($A8,$A$16:$G$18,5,FALSE)+M8*VLOOKUP($A8,$A$16:$G$18,6,FALSE)+N8*VLOOKUP($A8,$A$16:$G$18,7,FALSE) -> 65.49801 | P8: =COUNTIFS($A$2:$A$11,A8,$O$2:$O$11,">"&O8)+1 -> 1 | Q8: =IF(P8=1,"Best option for "&A8,IF(P8=2,"Runner-up","Lower priority / validate further")) -> Best option for Premium
A9: ='[1]Input Metrics'!A17 -> Premium | B9: ='[1]Input Metrics'!B17 -> District 3 | C9: ='Scoring model_input'!C9 -> 3 | D9: ='Scoring model_input'!D9 -> 7482 | E9: ='Scoring model_input'!E9 -> 2494 | F9: ='Scoring model_input'!F9 -> 0.21428571 | G9: ='Scoring model_input'!G9 -> 0.53761587 | H9: ='Scoring model_input'!H9 -> 0.32333015 | I9: =IFERROR(0.6*((D9-_xlfn.MINIFS($D$2:$D$11,$A$2:$A$11,$A9))/(_xlfn.MAXIFS($D$2:$D$11,$A$2:$A$11,$A9)-_xlfn.MINIFS($D$2:$D$11,$A$2:$A$11,$A9))*100)+0.4*((E9-_xlfn.MINIFS($E$2:$E$11,$A$2:$A$11,$A9))/(_xlfn.MAXIFS($E$2:$E$11,$A$2:$A$11,$A9)-_xlfn.MINIFS($E$2:$E$11,$A$2:$A$11,$A9))*100),0) -> 51.389572 | J9: =IF(D9=0,45,IFERROR((_xlfn.MAXIFS($C$2:$C$11,$A$2:$A$11,$A9)-C9)/(_xlfn.MAXIFS($C$2:$C$11,$A$2:$A$11,$A9)-_xlfn.MINIFS($C$2:$C$11,$A$2:$A$11,$A9))*100,0)) -> 91.176471 | K9: =IFERROR((H9-_xlfn.MINIFS($H$2:$H$11,$A$2:$A$11,$A9))/(_xlfn.MAXIFS($H$2:$H$11,$A$2:$A$11,$A9)-_xlfn.MINIFS($H$2:$H$11,$A$2:$A$11,$A9))*100,0) -> 100 | L9: =((F9*100)*0.5)+((G9*100)*0.5) -> 37.595079 | M9: ='[1]Input Metrics'!J17 -> 55 | N9: ='[1]Input Metrics'!K17 -> 85 | O9: =I9*VLOOKUP($A9,$A$16:$G$18,2,FALSE)+J9*VLOOKUP($A9,$A$16:$G$18,3,FALSE)+K9*VLOOKUP($A9,$A$16:$G$18,4,FALSE)+L9*VLOOKUP($A9,$A$16:$G$18,5,FALSE)+M9*VLOOKUP($A9,$A$16:$G$18,6,FALSE)+N9*VLOOKUP($A9,$A$16:$G$18,7,FALSE) -> 64.605754 | P9: =COUNTIFS($A$2:$A$11,A9,$O$2:$O$11,">"&O9)+1 -> 2 | Q9: =IF(P9=1,"Best option for "&A9,IF(P9=2,"Runner-up","Lower priority / validate further")) -> Runner-up
